#VRML_SIM R2019a utf8
WorldInfo {
}
Viewpoint {
  orientation 0.11470826054664322 -0.9752695229768031 -0.1889216041509343 4.430254142138116
  position 1.1785354352571928 0.7041473654655032 -0.23487421759926197
}
TexturedBackground {
}
TexturedBackgroundLight {
}
Floor {
}
Robot {
  translation 0 0.15 0
  children [
    Shape {
      appearance PBRAppearance {
        baseColor 0.5411764705882353 0.8862745098039215 0.20392156862745098
      }
      geometry Box {
        size 0.1 0.3 0.1
      }
    }
    HingeJoint {
      jointParameters HingeJointParameters {
        axis 0 1 0
        anchor 0 0.2 0
      }
      device [
        RotationalMotor {
          name "servo_motor"
        }
      ]
      endPoint Solid {
        translation 0 0.2 0
        children [
          Shape {
            appearance PBRAppearance {
              baseColor 0.9372549019607843 0.1607843137254902 0.1607843137254902
            }
            geometry DEF G_REDBOX Box {
              size 0.1 0.1 0.1
            }
          }
        ]
        boundingObject USE G_REDBOX
        physics Physics {
        }
      }
    }
  ]
}
