#VRML_SIM R2019a utf8
WorldInfo {
}
Viewpoint {
  orientation 0.11470826054664322 -0.9752695229768031 -0.1889216041509343 4.430254142138116
  position 0.8967605504852727 0.5969810231007444 -0.16271722070275918
}
TexturedBackground {
}
TexturedBackgroundLight {
}
Floor {
}
Robot {
  translation 0 0.15 0
  children [
    Shape {
      appearance PBRAppearance {
        baseColor 0.5411764705882353 0.8862745098039215 0.20392156862745098
      }
      geometry Box {
        size 0.1 0.3 0.1
      }
    }
    HingeJoint {
      jointParameters HingeJointParameters {
        axis 0 1 0
        anchor 0 0.2 0
      }
      device [
        RotationalMotor {
          name "servo_motor"
          maxVelocity 13.1
          maxTorque 0.2157
        }
      ]
      endPoint Solid {
        translation 0 0.2 0
        children [
          Shape {
            appearance PBRAppearance {
              baseColor 0.9372549019607843 0.1607843137254902 0.1607843137254902
            }
            geometry DEF G_REDBOX Box {
              size 0.1 0.1 0.1
            }
          }
        ]
        boundingObject USE G_REDBOX
        physics Physics {
        }
      }
    }
  ]
  controller "robot2"
}
